Workbook
Name タスク_開始: '2026'!$E1
Name タスク_開始: '2027'!$E1
Name タスク_開始: #REF!
Name タスク_終了: '2026'!$F1
Name タスク_終了: '2027'!$F1
Name タスク_終了: #REF!
Name タスク_進捗状況: '2026'!$D1
Name タスク_進捗状況: '2027'!$D1
Name タスク_進捗状況: #REF!
Name プロジェクトの開始: '2027'!$E$3
Name プロジェクトの開始: '2026'!$E$3
Name 今日: TODAY()
Name 今日: TODAY()
Name 週表示: '2027'!$E$4
Name 週表示: '2026'!$E$4

Sheet 2026
A1: このワークシートでプロジェクトのスケジュール​​を作成します。 セル B1 には、このプロジェクトのタイトルを入力します。 このワークシートの使用方法に関する情報 (スクリーン リーダーの説明やブックの作成者など) は、"詳細情報" ワークシートに入ります。 列 A を下方に移動し続けると、さらに多くの情報を確認できます。 | B1: 2Dバイクカスタムガレージ
A2: セル B2 には会社の名前を入力します。 | B2: R4S1 ARMY
A3: セル B3 に、プロジェクト主任の名前を入力します。セル E3 には、プロジェクトの開始日を入力します。プロジェクトの開始: ラベルはセル C3 にあります。 | C3: プロジェクトの開始: | E3: 46321
A4: セル E4 の週表示は、セル I4 のプロジェクトのスケジュールに表示する開始週を表します。プロジェクトの開始日は、第 1 週と見なされます。週表示を変更するには、セル E4 に新しい週番号を入力します。 セル E4 の週表示から始まる各週の開始日は、セル I4 から始まり、自動計算されます。このビューには、セル I4 からセル BF4 までの 8 週間が表示されます。 これらのセルは変更しないでください。 週表示: ラベルはセル C4 にあります。 | C4: 週表示: | E4: 1 | I4: =I5 -> 46321 | P4: =P5 -> 46328 | W4: =W5 -> 46335 | AD4: =AD5 -> 46342 | AK4: =AK5 -> 46349 | AR4: =AR5 -> 46356 | AY4: =AY5 -> 46363 | BF4: =BF5 -> 46370
A5: セル I5 から BL5 には、各日付のセルの上にあるセル ブロック内に表示される週の日付の数字が含まれており、自動的に計算が行われます。 これらのセルは変更しないでください。 今日の日付は、行 5 の今日の日付からプロジェクト スケジュールの最後まで日付列全体が赤 (16 進値 #AD3815) で囲まれます。 | I5: =プロジェクトの開始-WEEKDAY(プロジェクトの開始,1)+2+7*(週表示-1) -> 46321 | J5: =I5+1 -> 46322 | K5: =J5+1 -> 46323 | L5: =K5+1 -> 46324 | M5: =L5+1 -> 46325 | N5: =M5+1 -> 46326 | O5: =N5+1 -> 46327 | P5: =O5+1 -> 46328 | Q5: =P5+1 -> 46329 | ... BL5: =BK5+1 -> 46376
A6: この行には、その下に続くプロジェクトのスケジュールの見出しが含まれます。 コンテンツを読み上げるには、B6 から BL 6 に移動します。その見出しの上にある日付の各曜日の最初の文字が、セル I6 から始まってセル BL6 まで続きます。 すべてのプロジェクトのタイムライン グラフは、条件付き書式を使用して、入力された開始日と終了日に基づいて自動生成されます。 セル I7 から始まる列 I 以降の列のセルの内容を変更しないでください。 | B6: タスク | C6: 担当者 | D6: 進捗状況 | E6: 開始 | F6: 終了 | H6: 日数 | I6: =LEFT(TEXT(I5,"aaa"),1) -> 月 | J6: =LEFT(TEXT(J5,"aaa"),1) -> 火 | K6: =LEFT(TEXT(K5,"aaa"),1) -> 水 | L6: =LEFT(TEXT(L5,"aaa"),1) -> 木 | M6: =LEFT(TEXT(M5,"aaa"),1) -> 金 | N6: =LEFT(TEXT(N5,"aaa"),1) -> 土 | O6: =LEFT(TEXT(O5,"aaa"),1) -> 日 | P6: =LEFT(TEXT(P5,"aaa"),1) -> 月 | ... BL6: =LEFT(TEXT(BL5,"aaa"),1) -> 日
A7: この行は削除しないでください。この行は、プロジェクトのスケジュール内にある現在の日付を強調表示するために使用されている数式を保持するために非表示になっています。 | H7: =IF(OR(ISBLANK(タスク_開始),ISBLANK(タスク_終了)),"",タスク_終了-タスク_開始+1)
A8: セル B8 には、フェーズ 1 のサンプルのタイトルが含まれます。 セル B8 に新しいタイトルを入力します。 プロジェクトに該当する場合は、セル C8 にフェーズを割り当てる名前を入力します。 プロジェクトに該当する場合は、セル D8 にフェーズ全体の進捗状況を入力します。 プロジェクトに該当する場合は、フェーズ全体の開始日と終了日をセル E8 と F8 に入力します。 ガント チャートは自動的に適切な日付を入力し、入力した進捗状況に応じて網かけを設定します。 フェーズを削除してタスクからのみ作業をするには、この行を削除するだけです。 | B8: 1.基本設計書 | H8: =IF(OR(ISBLANK(タスク_開始),ISBLANK(タスク_終了)),"",タスク_終了-タスク_開始+1)
A9: セル B9 には、サンプル タスク "タスク 1" が含まれます。 セル B9 に、新しいタスク名を入力します。 セル C9 にタスクを割り当てるユーザーを入力します。 セル D9 のタスクの進捗状況を入力します。進行状況バーは、セル内に表示され、セルの数に従って網かけを適用します。たとえば、50% の進捗状況はセルの半分に網かけを設定します。 セル E9 にタスクの開始日を入力します。 セル F9 にタスクの終了日を入力します。 入力した日付の網かけのステータス バーは、セル I9 から始まる BL9 までのブロックに表示されます。 | B9: システム構築方針 | C9: 上釜 | D9: 0.8 | E9: 46316 | F9: 46326 | H9: =IF(OR(ISBLANK(タスク_開始),ISBLANK(タスク_終了)),"",タスク_終了-タスク_開始+1) -> 11
A10: 行 10 から 13 は、行 9 のパターンを繰り返します。 このワークシート内のすべてのタスク行に対し、セル A9 の手順を繰り返します。サンプル データはすべて上書きします。 別のフェーズのサンプルは、セル A14 から始まります。 セル A10 から A13 までにタスクの入力を続けるか、セル A14 に移動して詳細を確認します。 | B10: 制約条件・前提条件 | C10: 上釜 | D10: 0.8 | E10: 46316 | F10: 46326 | H10: =IF(OR(ISBLANK(タスク_開始),ISBLANK(タスク_終了)),"",タスク_終了-タスク_開始+1) -> 11
B11: システム概要 | C11: 上釜 | D11: 0.8 | E11: 46316 | F11: 46326 | H11: =IF(OR(ISBLANK(タスク_開始),ISBLANK(タスク_終了)),"",タスク_終了-タスク_開始+1) -> 11
B12: システム構成 | C12: 上釜 | D12: 0.8 | E12: 46316 | F12: 46326 | H12: =IF(OR(ISBLANK(タスク_開始),ISBLANK(タスク_終了)),"",タスク_終了-タスク_開始+1) -> 11
B13: 機能設計（詳細は、2.機能設計） | C13: 全員 | D13: 0.8 | E13: 46316 | F13: 46339 | H13: =IF(OR(ISBLANK(タスク_開始),ISBLANK(タスク_終了)),"",タスク_終了-タスク_開始+1) -> 24
B14: 画面設計（詳細は、3.画面設計） | C14: 全員 | D14: 0.8 | E14: 46316 | F14: 46339 | H14: =IF(OR(ISBLANK(タスク_開始),ISBLANK(タスク_終了)),"",タスク_終了-タスク_開始+1) -> 24
B15: 帳票設計 | C15: 江副 | D15: 0.8 | E15: 46316 | F15: 46339 | H15: =IF(OR(ISBLANK(タスク_開始),ISBLANK(タスク_終了)),"",タスク_終了-タスク_開始+1) -> 24
B16: DB設計（詳細は、4.DB設計） | C16: 全員 | D16: 0.8 | E16: 46316 | F16: 46339 | H16: =IF(OR(ISBLANK(タスク_開始),ISBLANK(タスク_終了)),"",タスク_終了-タスク_開始+1) -> 24
B17: コード設計（詳細は、5.コード設計） | C17: 全員 | D17: 0.8 | E17: 46316 | F17: 46339 | H17: =IF(OR(ISBLANK(タスク_開始),ISBLANK(タスク_終了)),"",タスク_終了-タスク_開始+1) -> 24
B18: 性能・運用・信頼性設計（詳細は、6.性能・運用設計） | C18: 全員 | D18: 0.8 | E18: 46316 | F18: 46339 | H18: =IF(OR(ISBLANK(タスク_開始),ISBLANK(タスク_終了)),"",タスク_終了-タスク_開始+1) -> 24
B19: 各種設計図（詳細は、7.設計図） | C19: 全員 | D19: 0.6 | E19: 46316 | F19: 46356 | H19: =IF(OR(ISBLANK(タスク_開始),ISBLANK(タスク_終了)),"",タスク_終了-タスク_開始+1) -> 41
B20: プログラミング（詳細は、8.プログラミング） | C20: 全員 | E20: 46327 | F20: 46402 | H20: =IF(OR(ISBLANK(タスク_開始),ISBLANK(タスク_終了)),"",タスク_終了-タスク_開始+1) -> 76
B21: 各種テスト（詳細は、9.各種テスト） | C21: 全員 | E21: 46327 | F21: 46402 | H21: =IF(OR(ISBLANK(タスク_開始),ISBLANK(タスク_終了)),"",タスク_終了-タスク_開始+1) -> 76
B22: 発表準備（詳細は、10.発表準備） | C22: 全員 | E22: 46405 | F22: 46409 | H22: =IF(OR(ISBLANK(タスク_開始),ISBLANK(タスク_終了)),"",タスク_終了-タスク_開始+1) -> 5
B23: 内部発表 | C23: 全員 | E23: 46412 | F23: 46421 | H23: =IF(OR(ISBLANK(タスク_開始),ISBLANK(タスク_終了)),"",タスク_終了-タスク_開始+1) -> 10
B24: 外部発表 | C24: － | E24: 46427 | F24: 46427 | H24: =IF(OR(ISBLANK(タスク_開始),ISBLANK(タスク_終了)),"",タスク_終了-タスク_開始+1) -> 1
A25: 右のセルには、フェーズ 2 のサンプルのタイトルが含まれます。 B 列に、いつでも新しいフェーズを作成できます。このプロジェクトのスケジュールには、フェーズは不要です。フェーズを削除するには、行を削除するだけです。 この行に新しいフェーズ ブロックを作成するには、右のセルに新しいタイトルを入力します。 上記のフェーズにタスクの追加を続けるには、この行の 1 つ上に新しい行を入力し、セル A9 の説明のようにタスク データを入力します。 セル A8 の説明に基づいて右側のセルのフェーズの詳細情報を更新します。 詳細については、A 列のセルを下に移動します。 このワークシートに新しい行を追加していない場合は、セル B20 と B26 に 2 つの追加のサンプル フェーズ ブロックが作成され表示されます。それ以外の場合、A 列のセルを移動して追加のブロックを探します。 必要に応じて、セル A8 と A9 の手順を繰り返します。 | B25: 2.機能設計 | H25: =IF(OR(ISBLANK(タスク_開始),ISBLANK(タスク_終了)),"",タスク_終了-タスク_開始+1)
B26: 機能一覧の洗い出し | C26: 上釜 | D26: 0.8 | E26: 46321 | F26: 46322 | H26: =IF(OR(ISBLANK(タスク_開始),ISBLANK(タスク_終了)),"",タスク_終了-タスク_開始+1) -> #VALUE!
B27: 2-01.車両ベース選択機能 | C27: 上釜 | D27: 0.8 | E27: 46323 | F27: 46324 | H27: =IF(OR(ISBLANK(タスク_開始),ISBLANK(タスク_終了)),"",タスク_終了-タスク_開始+1) -> #VALUE!
B28: 2-02.ベース車両追加機能 | C28: 和合 | D28: 0.8 | E28: 46326 | F28: 46329 | H28: =IF(OR(ISBLANK(タスク_開始),ISBLANK(タスク_終了)),"",タスク_終了-タスク_開始+1) -> #VALUE!
B29: 2-03.パーツ追加機能 | C29: 和合 | D29: 0.8 | E29: 46330 | F29: 46332 | H29: =IF(OR(ISBLANK(タスク_開始),ISBLANK(タスク_終了)),"",タスク_終了-タスク_開始+1) -> #VALUE!
B30: 2-04.組み合わせ制約機能 | C30: 上釜 | D30: 0.8 | E30: 46329 | F30: 46331 | H30: =IF(OR(ISBLANK(タスク_開始),ISBLANK(タスク_終了)),"",タスク_終了-タスク_開始+1) -> #VALUE!
B31: 2-05.パーツ・塗装選択機能 | C31: 上釜 | D31: 0.8 | E31: 46325 | F31: 46328 | H31: =IF(OR(ISBLANK(タスク_開始),ISBLANK(タスク_終了)),"",タスク_終了-タスク_開始+1) -> #VALUE!
B32: 2-06.取り消し機能 | C32: 江副 | D32: 0.8 | E32: 46323 | F32: 46324 | H32: =IF(OR(ISBLANK(タスク_開始),ISBLANK(タスク_終了)),"",タスク_終了-タスク_開始+1) -> #VALUE!
B33: 2-07.ビフォーアフター比較機能 | C33: 江副 | D33: 0.8 | E33: 46325 | F33: 46328 | H33: =IF(OR(ISBLANK(タスク_開始),ISBLANK(タスク_終了)),"",タスク_終了-タスク_開始+1) -> #VALUE!
B34: 2-08.仕様保存・呼出機能 | C34: 和合 | D34: 0.8 | E34: 46323 | F34: 46325 | H34: =IF(OR(ISBLANK(タスク_開始),ISBLANK(タスク_終了)),"",タスク_終了-タスク_開始+1) -> #VALUE!
B35: 2-09.PDF保存機能 | C35: 江副 | D35: 0.8 | E35: 46329 | F35: 46331 | H35: =IF(OR(ISBLANK(タスク_開始),ISBLANK(タスク_終了)),"",タスク_終了-タスク_開始+1) -> #VALUE!
B36: 2-10.管理者ログイン機能 | C36: 上釜 | D36: 0.8 | E36: 46332 | F36: 46335 | H36: =IF(OR(ISBLANK(タスク_開始),ISBLANK(タスク_終了)),"",タスク_終了-タスク_開始+1) -> #VALUE!
B37: 2-11.○○機能 | H37: =IF(OR(ISBLANK(タスク_開始),ISBLANK(タスク_終了)),"",タスク_終了-タスク_開始+1) -> #VALUE!
B38: 2-12.○○機能 | H38: =IF(OR(ISBLANK(タスク_開始),ISBLANK(タスク_終了)),"",タスク_終了-タスク_開始+1) -> #VALUE!
B39: 2-13.○○機能 | H39: =IF(OR(ISBLANK(タスク_開始),ISBLANK(タスク_終了)),"",タスク_終了-タスク_開始+1) -> #VALUE!
B40: 2-14.○○機能 | H40: =IF(OR(ISBLANK(タスク_開始),ISBLANK(タスク_終了)),"",タスク_終了-タスク_開始+1) -> #VALUE!
...

Sheet 2027
A1: このワークシートでプロジェクトのスケジュール​​を作成します。 セル B1 には、このプロジェクトのタイトルを入力します。 このワークシートの使用方法に関する情報 (スクリーン リーダーの説明やブックの作成者など) は、"詳細情報" ワークシートに入ります。 列 A を下方に移動し続けると、さらに多くの情報を確認できます。 | B1: ='2026'!B1&"("&YEAR(プロジェクトの開始)&")" -> 2Dバイクカスタムガレージ(2027) | G1: sotsuken
A2: セル B2 には会社の名前を入力します。 | B2: ='2026'!B2 -> チーム名を入力
A3: セル B3 に、プロジェクト主任の名前を入力します。セル E3 には、プロジェクトの開始日を入力します。プロジェクトの開始: ラベルはセル C3 にあります。 | C3: プロジェクトの開始: | E3: 46391
A4: セル E4 の週表示は、セル I4 のプロジェクトのスケジュールに表示する開始週を表します。プロジェクトの開始日は、第 1 週と見なされます。週表示を変更するには、セル E4 に新しい週番号を入力します。 セル E4 の週表示から始まる各週の開始日は、セル I4 から始まり、自動計算されます。このビューには、セル I4 からセル BF4 までの 8 週間が表示されます。 これらのセルは変更しないでください。 週表示: ラベルはセル C4 にあります。 | C4: 週表示: | E4: 1 | I4: =I5 -> 46391 | P4: =P5 -> 46398 | W4: =W5 -> 46405 | AD4: =AD5 -> 46412 | AK4: =AK5 -> 46419 | AR4: =AR5 -> 46426 | AY4: =AY5 -> 46433 | BF4: =BF5 -> 46440
A5: セル I5 から BL5 には、各日付のセルの上にあるセル ブロック内に表示される週の日付の数字が含まれており、自動的に計算が行われます。 これらのセルは変更しないでください。 今日の日付は、行 5 の今日の日付からプロジェクト スケジュールの最後まで日付列全体が赤 (16 進値 #AD3815) で囲まれます。 | I5: =プロジェクトの開始-WEEKDAY(プロジェクトの開始,1)+2+7*(週表示-1) -> 46391 | J5: =I5+1 -> 46392 | K5: =J5+1 -> 46393 | L5: =K5+1 -> 46394 | M5: =L5+1 -> 46395 | N5: =M5+1 -> 46396 | O5: =N5+1 -> 46397 | P5: =O5+1 -> 46398 | Q5: =P5+1 -> 46399 | ... BL5: =BK5+1 -> 46446
A6: この行には、その下に続くプロジェクトのスケジュールの見出しが含まれます。 コンテンツを読み上げるには、B6 から BL 6 に移動します。その見出しの上にある日付の各曜日の最初の文字が、セル I6 から始まってセル BL6 まで続きます。 すべてのプロジェクトのタイムライン グラフは、条件付き書式を使用して、入力された開始日と終了日に基づいて自動生成されます。 セル I7 から始まる列 I 以降の列のセルの内容を変更しないでください。 | B6: タスク | C6: 担当者 | D6: 進捗状況 | E6: 開始 | F6: 終了 | H6: 日数 | I6: =LEFT(TEXT(I5,"aaa"),1) -> 月 | J6: =LEFT(TEXT(J5,"aaa"),1) -> 火 | K6: =LEFT(TEXT(K5,"aaa"),1) -> 水 | L6: =LEFT(TEXT(L5,"aaa"),1) -> 木 | M6: =LEFT(TEXT(M5,"aaa"),1) -> 金 | N6: =LEFT(TEXT(N5,"aaa"),1) -> 土 | O6: =LEFT(TEXT(O5,"aaa"),1) -> 日 | P6: =LEFT(TEXT(P5,"aaa"),1) -> 月 | ... BL6: =LEFT(TEXT(BL5,"aaa"),1) -> 日
A7: この行は削除しないでください。この行は、プロジェクトのスケジュール内にある現在の日付を強調表示するために使用されている数式を保持するために非表示になっています。 | H7: =IF(OR(ISBLANK(タスク_開始),ISBLANK(タスク_終了)),"",タスク_終了-タスク_開始+1)
A8: セル B8 には、フェーズ 1 のサンプルのタイトルが含まれます。 セル B8 に新しいタイトルを入力します。 プロジェクトに該当する場合は、セル C8 にフェーズを割り当てる名前を入力します。 プロジェクトに該当する場合は、セル D8 にフェーズ全体の進捗状況を入力します。 プロジェクトに該当する場合は、フェーズ全体の開始日と終了日をセル E8 と F8 に入力します。 ガント チャートは自動的に適切な日付を入力し、入力した進捗状況に応じて網かけを設定します。 フェーズを削除してタスクからのみ作業をするには、この行を削除するだけです。 | B8: 1.基本設計書 | H8: =IF(OR(ISBLANK(タスク_開始),ISBLANK(タスク_終了)),"",タスク_終了-タスク_開始+1)
A9: セル B9 には、サンプル タスク "タスク 1" が含まれます。 セル B9 に、新しいタスク名を入力します。 セル C9 にタスクを割り当てるユーザーを入力します。 セル D9 のタスクの進捗状況を入力します。進行状況バーは、セル内に表示され、セルの数に従って網かけを適用します。たとえば、50% の進捗状況はセルの半分に網かけを設定します。 セル E9 にタスクの開始日を入力します。 セル F9 にタスクの終了日を入力します。 入力した日付の網かけのステータス バーは、セル I9 から始まる BL9 までのブロックに表示されます。 | B9: システム構築方針 | C9: ='2026'!C9 | D9: ='2026'!D9 -> 0.8 | E9: ='2026'!E9 -> 46316 | F9: ='2026'!F9 -> 46326 | H9: =IF(OR(ISBLANK(タスク_開始),ISBLANK(タスク_終了)),"",タスク_終了-タスク_開始+1) -> 11
A10: 行 10 から 13 は、行 9 のパターンを繰り返します。 このワークシート内のすべてのタスク行に対し、セル A9 の手順を繰り返します。サンプル データはすべて上書きします。 別のフェーズのサンプルは、セル A14 から始まります。 セル A10 から A13 までにタスクの入力を続けるか、セル A14 に移動して詳細を確認します。 | B10: 制約条件・前提条件 | C10: ='2026'!C10 | D10: ='2026'!D10 -> 0.8 | E10: ='2026'!E10 -> 46316 | F10: ='2026'!F10 -> 46326 | H10: =IF(OR(ISBLANK(タスク_開始),ISBLANK(タスク_終了)),"",タスク_終了-タスク_開始+1) -> 11
B11: システム概要 | C11: ='2026'!C11 | D11: ='2026'!D11 -> 0.6 | E11: ='2026'!E11 -> 46316 | F11: ='2026'!F11 -> 46326 | H11: =IF(OR(ISBLANK(タスク_開始),ISBLANK(タスク_終了)),"",タスク_終了-タスク_開始+1) -> 11
B12: システム構成 | C12: ='2026'!C12 | D12: ='2026'!D12 -> 0.6 | E12: ='2026'!E12 -> 46316 | F12: ='2026'!F12 -> 46326 | H12: =IF(OR(ISBLANK(タスク_開始),ISBLANK(タスク_終了)),"",タスク_終了-タスク_開始+1) -> 11
B13: 機能設計（詳細は、2.機能設計） | C13: ='2026'!C13 -> 全員 | D13: ='2026'!D13 -> 0 | E13: ='2026'!E13 -> 46316 | F13: ='2026'!F13 -> 46339 | H13: =IF(OR(ISBLANK(タスク_開始),ISBLANK(タスク_終了)),"",タスク_終了-タスク_開始+1) -> 24
B14: 画面設計（詳細は、3.画面設計） | C14: ='2026'!C14 -> 全員 | D14: ='2026'!D14 -> 0 | E14: ='2026'!E14 -> 46316 | F14: ='2026'!F14 -> 46339 | H14: =IF(OR(ISBLANK(タスク_開始),ISBLANK(タスク_終了)),"",タスク_終了-タスク_開始+1) -> 24
B15: 帳票設計 | C15: ='2026'!C15 | D15: ='2026'!D15 -> 0 | E15: ='2026'!E15 -> 46316 | F15: ='2026'!F15 -> 46339 | H15: =IF(OR(ISBLANK(タスク_開始),ISBLANK(タスク_終了)),"",タスク_終了-タスク_開始+1) -> 24
B16: DB設計（詳細は、4.DB設計） | C16: ='2026'!C16 -> 全員 | D16: ='2026'!D16 -> 0 | E16: ='2026'!E16 -> 46316 | F16: ='2026'!F16 -> 46339 | H16: =IF(OR(ISBLANK(タスク_開始),ISBLANK(タスク_終了)),"",タスク_終了-タスク_開始+1) -> 24
B17: コード設計（詳細は、5.コード設計） | C17: ='2026'!C17 -> 全員 | D17: ='2026'!D17 -> 0 | E17: ='2026'!E17 -> 46316 | F17: ='2026'!F17 -> 46339 | H17: =IF(OR(ISBLANK(タスク_開始),ISBLANK(タスク_終了)),"",タスク_終了-タスク_開始+1) -> 24
B18: 性能・運用・信頼性設計（詳細は、6.性能・運用設計） | C18: ='2026'!C18 -> 全員 | D18: ='2026'!D18 -> 0 | E18: ='2026'!E18 -> 46316 | F18: ='2026'!F18 -> 46339 | H18: =IF(OR(ISBLANK(タスク_開始),ISBLANK(タスク_終了)),"",タスク_終了-タスク_開始+1) -> 24
B19: 各種設計図（詳細は、7.設計図） | C19: ='2026'!C19 -> 全員 | D19: ='2026'!D19 -> 0 | E19: ='2026'!E19 -> 46316 | F19: ='2026'!F19 -> 46356 | H19: =IF(OR(ISBLANK(タスク_開始),ISBLANK(タスク_終了)),"",タスク_終了-タスク_開始+1) -> 41
B20: プログラミング（詳細は、8.プログラミング） | C20: ='2026'!C20 -> 全員 | D20: ='2026'!D20 -> 0 | E20: ='2026'!E20 -> 46327 | F20: ='2026'!F20 -> 46402 | H20: =IF(OR(ISBLANK(タスク_開始),ISBLANK(タスク_終了)),"",タスク_終了-タスク_開始+1) -> 76
B21: 各種テスト（詳細は、9.各種テスト） | C21: ='2026'!C21 -> 全員 | D21: ='2026'!D21 -> 0 | E21: ='2026'!E21 -> 46327 | F21: ='2026'!F21 -> 46402 | H21: =IF(OR(ISBLANK(タスク_開始),ISBLANK(タスク_終了)),"",タスク_終了-タスク_開始+1) -> 76
B22: 発表準備（詳細は、10.発表準備） | C22: ='2026'!C22 -> 全員 | D22: ='2026'!D22 -> 0 | E22: ='2026'!E22 -> 46405 | F22: ='2026'!F22 -> 46409 | H22: =IF(OR(ISBLANK(タスク_開始),ISBLANK(タスク_終了)),"",タスク_終了-タスク_開始+1) -> 5
... B24: 外部発表 | C24: ='2026'!C24 -> － | D24: ='2026'!D24 -> 0 | E24: ='2026'!E24 -> 46427 | F24: ='2026'!F24 -> 46427 | H24: =IF(OR(ISBLANK(タスク_開始),ISBLANK(タスク_終了)),"",タスク_終了-タスク_開始+1) -> 1
A25: 右のセルには、フェーズ 2 のサンプルのタイトルが含まれます。 B 列に、いつでも新しいフェーズを作成できます。このプロジェクトのスケジュールには、フェーズは不要です。フェーズを削除するには、行を削除するだけです。 この行に新しいフェーズ ブロックを作成するには、右のセルに新しいタイトルを入力します。 上記のフェーズにタスクの追加を続けるには、この行の 1 つ上に新しい行を入力し、セル A9 の説明のようにタスク データを入力します。 セル A8 の説明に基づいて右側のセルのフェーズの詳細情報を更新します。 詳細については、A 列のセルを下に移動します。 このワークシートに新しい行を追加していない場合は、セル B20 と B26 に 2 つの追加のサンプル フェーズ ブロックが作成され表示されます。それ以外の場合、A 列のセルを移動して追加のブロックを探します。 必要に応じて、セル A8 と A9 の手順を繰り返します。 | B25: 2.機能設計 | H25: =IF(OR(ISBLANK(タスク_開始),ISBLANK(タスク_終了)),"",タスク_終了-タスク_開始+1)
B26: ='2026'!B26 -> 機能一覧の洗い出し | C26: ='2026'!C26 | D26: ='2026'!D26 | E26: ='2026'!E26 | F26: ='2026'!F26 | H26: =IF(OR(ISBLANK(タスク_開始),ISBLANK(タスク_終了)),"",タスク_終了-タスク_開始+1) -> #VALUE!
B27: ='2026'!B27 -> 2-01.車両ベース選択機能 | C27: ='2026'!C27 | D27: ='2026'!D27 | E27: ='2026'!E27 | F27: ='2026'!F27 | H27: =IF(OR(ISBLANK(タスク_開始),ISBLANK(タスク_終了)),"",タスク_終了-タスク_開始+1) -> #VALUE!
B28: ='2026'!B28 -> 2-02.ベース車両追加機能 | C28: ='2026'!C28 | D28: ='2026'!D28 | E28: ='2026'!E28 | F28: ='2026'!F28 | H28: =IF(OR(ISBLANK(タスク_開始),ISBLANK(タスク_終了)),"",タスク_終了-タスク_開始+1) -> #VALUE!
B29: ='2026'!B29 -> 2-03.パーツ追加機能 | C29: ='2026'!C29 | D29: ='2026'!D29 | E29: ='2026'!E29 | F29: ='2026'!F29 | H29: =IF(OR(ISBLANK(タスク_開始),ISBLANK(タスク_終了)),"",タスク_終了-タスク_開始+1) -> #VALUE!
B30: ='2026'!B30 -> 2-04.組み合わせ制約機能 | C30: ='2026'!C30 | D30: ='2026'!D30 | E30: ='2026'!E30 | F30: ='2026'!F30 | H30: =IF(OR(ISBLANK(タスク_開始),ISBLANK(タスク_終了)),"",タスク_終了-タスク_開始+1) -> #VALUE!
B31: ='2026'!B31 -> 2-05.パーツ・塗装選択機能 | C31: ='2026'!C31 | D31: ='2026'!D31 | E31: ='2026'!E31 | F31: ='2026'!F31 | H31: =IF(OR(ISBLANK(タスク_開始),ISBLANK(タスク_終了)),"",タスク_終了-タスク_開始+1) -> #VALUE!
B32: ='2026'!B32 -> 2-06.取り消し機能 | C32: ='2026'!C32 | D32: ='2026'!D32 | E32: ='2026'!E32 | F32: ='2026'!F32 | H32: =IF(OR(ISBLANK(タスク_開始),ISBLANK(タスク_終了)),"",タスク_終了-タスク_開始+1) -> #VALUE!
B33: ='2026'!B33 -> 2-07.ビフォーアフター比較機能 | C33: ='2026'!C33 | D33: ='2026'!D33 | E33: ='2026'!E33 | F33: ='2026'!F33 | H33: =IF(OR(ISBLANK(タスク_開始),ISBLANK(タスク_終了)),"",タスク_終了-タスク_開始+1) -> #VALUE!
B34: ='2026'!B34 -> 2-08.仕様保存・呼出機能 | C34: ='2026'!C34 | D34: ='2026'!D34 | E34: ='2026'!E34 | F34: ='2026'!F34 | H34: =IF(OR(ISBLANK(タスク_開始),ISBLANK(タスク_終了)),"",タスク_終了-タスク_開始+1) -> #VALUE!
B35: ='2026'!B35 -> 2-09.PDF保存機能 | C35: ='2026'!C35 | D35: ='2026'!D35 | E35: ='2026'!E35 | F35: ='2026'!F35 | H35: =IF(OR(ISBLANK(タスク_開始),ISBLANK(タスク_終了)),"",タスク_終了-タスク_開始+1) -> #VALUE!
B36: ='2026'!B36 -> 2-10.共有機能 | C36: ='2026'!C36 | D36: ='2026'!D36 | E36: ='2026'!E36 | F36: ='2026'!F36 | H36: =IF(OR(ISBLANK(タスク_開始),ISBLANK(タスク_終了)),"",タスク_終了-タスク_開始+1) -> #VALUE!
B37: ='2026'!B37 -> 2-11.○○機能 | C37: ='2026'!C37 | D37: ='2026'!D37 | E37: ='2026'!E37 | F37: ='2026'!F37 | H37: =IF(OR(ISBLANK(タスク_開始),ISBLANK(タスク_終了)),"",タスク_終了-タスク_開始+1) -> #VALUE!
... B56: ='2026'!B56 -> 2-30.○○機能 | C56: ='2026'!C56 | D56: ='2026'!D56 | E56: ='2026'!E56 | F56: ='2026'!F56 | H56: =IF(OR(ISBLANK(タスク_開始),ISBLANK(タスク_終了)),"",タスク_終了-タスク_開始+1) -> #VALUE!
A57: サンプル フェーズ タイトル ブロック | B57: 3.画面設計 | H57: =IF(OR(ISBLANK(タスク_開始),ISBLANK(タスク_終了)),"",タスク_終了-タスク_開始+1)
B58: ='2026'!B58 -> 画面一覧の洗い出し | C58: ='2026'!C58 | D58: ='2026'!D58 | E58: ='2026'!E58 | F58: ='2026'!F58 | H58: =IF(OR(ISBLANK(タスク_開始),ISBLANK(タスク_終了)),"",タスク_終了-タスク_開始+1) -> #VALUE!
B59: ='2026'!B59 -> 画面遷移図 | C59: ='2026'!C59 | D59: ='2026'!D59 | E59: ='2026'!E59 | F59: ='2026'!F59 | H59: =IF(OR(ISBLANK(タスク_開始),ISBLANK(タスク_終了)),"",タスク_終了-タスク_開始+1) -> #VALUE!
...

Sheet 詳細情報
A2: シンプル ガント チャート (Vertex42.com)
A3: https://www.vertex42.com/ExcelTemplates/simple-gantt-chart.html
A4: このテンプレートについて
A5: このテンプレートを使用すると、プロジェクトの視覚化と管理に役立つガント チャートを簡単な方法で作成できます。タスクと開始日、終了日を入力するだけです。数式の入力は必要はありません。ガント チャートのバーは、タスクの期間を表し、条件付き書式を使用して表示されます。新しいタスクを挿入するには、新しい行を挿入します。
A6: スクリーン リーダーのガイド
A7: このブックには 2 つのワークシートがあります。 タイムシート 詳細情報 各ワークシートの説明は、各ワークシートの A 列のセル A1 から始まります。非表示のテキストで書き込まれます。各手順では、その行に含まれる情報について説明しています。明示的な指示がない限り、後続の各手順はセル A2、セル A3 といった順に格納されています。たとえば、説明テキストに、次の手順について "セル A6 に続く" と記載されている場合があります。 この非表示のテキストは印刷されません。 ワークシートからこれらの説明を削除する場合は、A 列を削除するだけです。
A8: その他のヘルプ
A9: 以下のリンクから Vertex42.com にアクセスし、このテンプレートの使用方法を詳しく学びます。たとえば、日数と稼働日の計算、タスクの依存関係を作成する、バーの色の変更、週表示を簡単に変更するためのスクロール バーを追加する方法、グラフに表示される日付範囲の拡大方法など。
A10: シンプル ガント チャートの使用方法
A11: その他のプロジェクト管理テンプレート
A12: Vertex42.com にアクセスして、さまざまな種類のプロジェクト スケジュール、ガント チャート、タスク リストなどのその他のプロジェクト管理テンプレートをダウンロードしてください。
A13: プロジェクト管理テンプレート
... A16: 企業向けには、請求書、タイム シート、在庫管理、財務諸表、プロジェクト計画策定テンプレートがあります。学生と教師向けには、授業計画表、成績表、出席簿などのリソースがあります。献立表、チェックリスト、運動記録を使用して家族の生活を整理しましょう。各テンプレートは、数千のユーザーからのフィードバックを基に時間をかけて十分に研究、調整、改良されたものです。
